Workbook

Sheet Résultats
A1: Tableau de Bord
A3: Auteurs :
A5: Mode d'emploi :
A6: 1. Saisissez une date de référence (D11)
A7: 2. La date doit être comprise entre la date de début d'étude et la date de fin de l'étude. | G7: Date | H7: Apprenti | I7: CDD | J7: CDI
C8: Début d'étude : | D8: 45536 | G8: 45536 | H8: {=SUM((Contrats[debut]<=Contratsactifsdébutdumois[[#This Row],[Date]])*(Contrats[fin_imputee]>=Contratsactifsdébutdumois[[#This Row],[Date]])*(Contrats[type]="apprenti"))} -> 0 | I8: {=SUM((Contrats[debut]<=Contratsactifsdébutdumois[[#This Row],[Date]])*(Contrats[fin_imputee]>=Contratsactifsdébutdumois[[#This Row],[Date]])*(Contrats[type]="cdd"))} -> 157 | J8: {=SUM((Contrats[debut]<=Contratsactifsdébutdumois[[#This Row],[Date]])*(Contrats[fin_imputee]>=Contratsactifsdébutdumois[[#This Row],[Date]])*(Contrats[type]="cdi"))} -> 881
C9: Fin d'étude : | D9: 45900 | G9: 45566 | H9: {=SUM((Contrats[debut]<=Contratsactifsdébutdumois[[#This Row],[Date]])*(Contrats[fin_imputee]>=Contratsactifsdébutdumois[[#This Row],[Date]])*(Contrats[type]="apprenti"))} -> 0 | I9: {=SUM((Contrats[debut]<=Contratsactifsdébutdumois[[#This Row],[Date]])*(Contrats[fin_imputee]>=Contratsactifsdébutdumois[[#This Row],[Date]])*(Contrats[type]="cdd"))} -> 157 | J9: {=SUM((Contrats[debut]<=Contratsactifsdébutdumois[[#This Row],[Date]])*(Contrats[fin_imputee]>=Contratsactifsdébutdumois[[#This Row],[Date]])*(Contrats[type]="cdi"))} -> 881
G10: 45597 | H10: {=SUM((Contrats[debut]<=Contratsactifsdébutdumois[[#This Row],[Date]])*(Contrats[fin_imputee]>=Contratsactifsdébutdumois[[#This Row],[Date]])*(Contrats[type]="apprenti"))} -> 0 | I10: {=SUM((Contrats[debut]<=Contratsactifsdébutdumois[[#This Row],[Date]])*(Contrats[fin_imputee]>=Contratsactifsdébutdumois[[#This Row],[Date]])*(Contrats[type]="cdd"))} -> 157 | J10: {=SUM((Contrats[debut]<=Contratsactifsdébutdumois[[#This Row],[Date]])*(Contrats[fin_imputee]>=Contratsactifsdébutdumois[[#This Row],[Date]])*(Contrats[type]="cdi"))} -> 881
C11: Date de référence : | D11: 45818 | G11: 45627 | H11: {=SUM((Contrats[debut]<=Contratsactifsdébutdumois[[#This Row],[Date]])*(Contrats[fin_imputee]>=Contratsactifsdébutdumois[[#This Row],[Date]])*(Contrats[type]="apprenti"))} -> 0 | I11: {=SUM((Contrats[debut]<=Contratsactifsdébutdumois[[#This Row],[Date]])*(Contrats[fin_imputee]>=Contratsactifsdébutdumois[[#This Row],[Date]])*(Contrats[type]="cdd"))} -> 157 | J11: {=SUM((Contrats[debut]<=Contratsactifsdébutdumois[[#This Row],[Date]])*(Contrats[fin_imputee]>=Contratsactifsdébutdumois[[#This Row],[Date]])*(Contrats[type]="cdi"))} -> 880
G12: 45658 | H12: {=SUM((Contrats[debut]<=Contratsactifsdébutdumois[[#This Row],[Date]])*(Contrats[fin_imputee]>=Contratsactifsdébutdumois[[#This Row],[Date]])*(Contrats[type]="apprenti"))} -> 0 | I12: {=SUM((Contrats[debut]<=Contratsactifsdébutdumois[[#This Row],[Date]])*(Contrats[fin_imputee]>=Contratsactifsdébutdumois[[#This Row],[Date]])*(Contrats[type]="cdd"))} -> 157 | J12: {=SUM((Contrats[debut]<=Contratsactifsdébutdumois[[#This Row],[Date]])*(Contrats[fin_imputee]>=Contratsactifsdébutdumois[[#This Row],[Date]])*(Contrats[type]="cdi"))} -> 880
G13: 45689 | H13: {=SUM((Contrats[debut]<=Contratsactifsdébutdumois[[#This Row],[Date]])*(Contrats[fin_imputee]>=Contratsactifsdébutdumois[[#This Row],[Date]])*(Contrats[type]="apprenti"))} -> 0 | I13: {=SUM((Contrats[debut]<=Contratsactifsdébutdumois[[#This Row],[Date]])*(Contrats[fin_imputee]>=Contratsactifsdébutdumois[[#This Row],[Date]])*(Contrats[type]="cdd"))} -> 157 | J13: {=SUM((Contrats[debut]<=Contratsactifsdébutdumois[[#This Row],[Date]])*(Contrats[fin_imputee]>=Contratsactifsdébutdumois[[#This Row],[Date]])*(Contrats[type]="cdi"))} -> 880
G14: 45717 | H14: {=SUM((Contrats[debut]<=Contratsactifsdébutdumois[[#This Row],[Date]])*(Contrats[fin_imputee]>=Contratsactifsdébutdumois[[#This Row],[Date]])*(Contrats[type]="apprenti"))} -> 0 | I14: {=SUM((Contrats[debut]<=Contratsactifsdébutdumois[[#This Row],[Date]])*(Contrats[fin_imputee]>=Contratsactifsdébutdumois[[#This Row],[Date]])*(Contrats[type]="cdd"))} -> 157 | J14: {=SUM((Contrats[debut]<=Contratsactifsdébutdumois[[#This Row],[Date]])*(Contrats[fin_imputee]>=Contratsactifsdébutdumois[[#This Row],[Date]])*(Contrats[type]="cdi"))} -> 880
G15: 45748 | H15: {=SUM((Contrats[debut]<=Contratsactifsdébutdumois[[#This Row],[Date]])*(Contrats[fin_imputee]>=Contratsactifsdébutdumois[[#This Row],[Date]])*(Contrats[type]="apprenti"))} -> 0 | I15: {=SUM((Contrats[debut]<=Contratsactifsdébutdumois[[#This Row],[Date]])*(Contrats[fin_imputee]>=Contratsactifsdébutdumois[[#This Row],[Date]])*(Contrats[type]="cdd"))} -> 157 | J15: {=SUM((Contrats[debut]<=Contratsactifsdébutdumois[[#This Row],[Date]])*(Contrats[fin_imputee]>=Contratsactifsdébutdumois[[#This Row],[Date]])*(Contrats[type]="cdi"))} -> 880
G16: 45778 | H16: {=SUM((Contrats[debut]<=Contratsactifsdébutdumois[[#This Row],[Date]])*(Contrats[fin_imputee]>=Contratsactifsdébutdumois[[#This Row],[Date]])*(Contrats[type]="apprenti"))} -> 0 | I16: {=SUM((Contrats[debut]<=Contratsactifsdébutdumois[[#This Row],[Date]])*(Contrats[fin_imputee]>=Contratsactifsdébutdumois[[#This Row],[Date]])*(Contrats[type]="cdd"))} -> 157 | J16: {=SUM((Contrats[debut]<=Contratsactifsdébutdumois[[#This Row],[Date]])*(Contrats[fin_imputee]>=Contratsactifsdébutdumois[[#This Row],[Date]])*(Contrats[type]="cdi"))} -> 880
G17: 45809 | H17: {=SUM((Contrats[debut]<=Contratsactifsdébutdumois[[#This Row],[Date]])*(Contrats[fin_imputee]>=Contratsactifsdébutdumois[[#This Row],[Date]])*(Contrats[type]="apprenti"))} -> 0 | I17: {=SUM((Contrats[debut]<=Contratsactifsdébutdumois[[#This Row],[Date]])*(Contrats[fin_imputee]>=Contratsactifsdébutdumois[[#This Row],[Date]])*(Contrats[type]="cdd"))} -> 157 | J17: {=SUM((Contrats[debut]<=Contratsactifsdébutdumois[[#This Row],[Date]])*(Contrats[fin_imputee]>=Contratsactifsdébutdumois[[#This Row],[Date]])*(Contrats[type]="cdi"))} -> 880
G18: 45839 | H18: {=SUM((Contrats[debut]<=Contratsactifsdébutdumois[[#This Row],[Date]])*(Contrats[fin_imputee]>=Contratsactifsdébutdumois[[#This Row],[Date]])*(Contrats[type]="apprenti"))} -> 0 | I18: {=SUM((Contrats[debut]<=Contratsactifsdébutdumois[[#This Row],[Date]])*(Contrats[fin_imputee]>=Contratsactifsdébutdumois[[#This Row],[Date]])*(Contrats[type]="cdd"))} -> 157 | J18: {=SUM((Contrats[debut]<=Contratsactifsdébutdumois[[#This Row],[Date]])*(Contrats[fin_imputee]>=Contratsactifsdébutdumois[[#This Row],[Date]])*(Contrats[type]="cdi"))} -> 880
G19: 45870 | H19: {=SUM((Contrats[debut]<=Contratsactifsdébutdumois[[#This Row],[Date]])*(Contrats[fin_imputee]>=Contratsactifsdébutdumois[[#This Row],[Date]])*(Contrats[type]="apprenti"))} -> 0 | I19: {=SUM((Contrats[debut]<=Contratsactifsdébutdumois[[#This Row],[Date]])*(Contrats[fin_imputee]>=Contratsactifsdébutdumois[[#This Row],[Date]])*(Contrats[type]="cdd"))} -> 157 | J19: {=SUM((Contrats[debut]<=Contratsactifsdébutdumois[[#This Row],[Date]])*(Contrats[fin_imputee]>=Contratsactifsdébutdumois[[#This Row],[Date]])*(Contrats[type]="cdi"))} -> 880

Sheet TCD
A3: Sum of actif_date_ref | B3: Column Labels
A4: Row Labels | B4: apprenti | C4: cdd | D4: cdi | E4: Grand Total
A5: Administratif | B5: 0 | C5: 17 | D5: 76 | E5: 93
A6: Administratif/médical | C6: 4 | D6: 17 | E6: 21
A7: Biomédical | B7: 0 | C7: 1 | D7: 11 | E7: 12
A8: Bloc opératoire | B8: 0 | C8: 18 | D8: 100 | E8: 118
A9: Direction | C9: 1 | D9: 5 | E9: 6
A10: Hygiène/Hôtellerie | B10: 0 | C10: 3 | D10: 14 | E10: 17
A11: Imagerie | B11: 0 | C11: 8 | D11: 26 | E11: 34
A12: Information médicale | C12: 3 | D12: 16 | E12: 19
A13: Juridique | B13: 0 | C13: 0 | D13: 2 | E13: 2
A14: Laboratoire | B14: 0 | C14: 5 | D14: 40 | E14: 45
A15: Logistique | B15: 0 | C15: 2 | D15: 19 | E15: 21
A16: Maïeutique | B16: 0 | C16: 0 | D16: 12 | E16: 12
A17: Médical | B17: 0 | C17: 27 | D17: 146 | E17: 173
A18: Pédiatrie/néonat | B18: 0 | C18: 0 | D18: 6 | E18: 6
A19: Pharmacie | B19: 0 | C19: 2 | D19: 39 | E19: 41
A20: Psycho-social | B20: 0 | C20: 1 | D20: 9 | E20: 10
A21: Qualité | B21: 0 | C21: 0 | D21: 7 | E21: 7
A22: Recherche | B22: 0 | C22: 0 | D22: 10 | E22: 10
A23: Rééducation | B23: 0 | C23: 4 | D23: 21 | E23: 25
A24: Sécurité | B24: 0 | C24: 2 | D24: 10 | E24: 12
A25: Soins infirmiers | B25: 0 | C25: 55 | D25: 280 | E25: 335
A26: Techniques/bâtiment | C26: 4 | D26: 14 | E26: 18
A27: Grand Total | B27: 0 | C27: 157 | D27: 880 | E27: 1037

Sheet contrats
D1: 45900
A2: id | B2: debut | C2: fin | D2: fin_imputee | E2: type | F2: id_pers | G2: id_emploi | H2: part_temps | I2: id_temps | J2: plage_type | K2: decompte_temps | L2: exempt_nuit | M2: exempt_astreinte | N2: exempt_bloc | O2: catégorie | P2: actif_date_ref
A3: 1 | B3: 37034 | C3: 37522 | D3: =IF(Contrats[[#This Row],[fin]]="",D$1, Contrats[[#This Row],[fin]]) -> 37522 | E3: cdi | F3: 1 | G3: 261 | H3: 0.8 | I3: 365 | J3: nuit | K3: heures | L3: 0 | M3: 1 | N3: 1 | O3: =VLOOKUP(Contrats[[#This Row],[id_emploi]],Emplois[#All],3,0) -> Soins infirmiers | P3: =IF(AND(Contrats[[#This Row],[debut]]<=Résultats!D$11,Contrats[[#This Row],[fin_imputee]]>=Résultats!D$11),1,0) -> 0
A4: 2 | B4: 37134 | C4: 37346 | D4: =IF(Contrats[[#This Row],[fin]]="",D$1, Contrats[[#This Row],[fin]]) -> 37346 | E4: cdi | F4: 2 | G4: 105 | H4: 1.0 | I4: 165 | J4: jour | K4: heures | L4: 1 | M4: 1 | N4: 1 | O4: =VLOOKUP(Contrats[[#This Row],[id_emploi]],Emplois[#All],3,0) -> Administratif | P4: =IF(AND(Contrats[[#This Row],[debut]]<=Résultats!D$11,Contrats[[#This Row],[fin_imputee]]>=Résultats!D$11),1,0) -> 0
A5: 3 | B5: 37404 | C5: 37618 | D5: =IF(Contrats[[#This Row],[fin]]="",D$1, Contrats[[#This Row],[fin]]) -> 37618 | E5: cdi | F5: 2 | G5: 105 | H5: 1.0 | I5: 165 | J5: jour | K5: heures | L5: 0 | M5: 1 | N5: 1 | O5: =VLOOKUP(Contrats[[#This Row],[id_emploi]],Emplois[#All],3,0) -> Administratif | P5: =IF(AND(Contrats[[#This Row],[debut]]<=Résultats!D$11,Contrats[[#This Row],[fin_imputee]]>=Résultats!D$11),1,0) -> 0
A6: 4 | B6: 40646 | C6: 40829 | D6: =IF(Contrats[[#This Row],[fin]]="",D$1, Contrats[[#This Row],[fin]]) -> 40829 | E6: cdd | F6: 3 | G6: 238 | H6: 0.8 | I6: 338 | J6: astreinte | K6: astreinte | L6: 0 | M6: 0 | N6: 1 | O6: =VLOOKUP(Contrats[[#This Row],[id_emploi]],Emplois[#All],3,0) -> Soins infirmiers | P6: =IF(AND(Contrats[[#This Row],[debut]]<=Résultats!D$11,Contrats[[#This Row],[fin_imputee]]>=Résultats!D$11),1,0) -> 0
A7: 5 | B7: 36552 | D7: =IF(Contrats[[#This Row],[fin]]="",D$1, Contrats[[#This Row],[fin]]) -> 45900 | E7: cdi | F7: 4 | G7: 216 | H7: 0.6 | I7: 309 | J7: forfait | K7: jours | L7: 0 | M7: 0 | N7: 1 | O7: =VLOOKUP(Contrats[[#This Row],[id_emploi]],Emplois[#All],3,0) -> Administratif | P7: =IF(AND(Contrats[[#This Row],[debut]]<=Résultats!D$11,Contrats[[#This Row],[fin_imputee]]>=Résultats!D$11),1,0) -> 1
A8: 6 | B8: 37516 | C8: 37911 | D8: =IF(Contrats[[#This Row],[fin]]="",D$1, Contrats[[#This Row],[fin]]) -> 37911 | E8: cdd | F8: 5 | G8: 51 | H8: 1.0 | I8: 101 | J8: nuit | K8: heures | L8: 0 | M8: 1 | N8: 1 | O8: =VLOOKUP(Contrats[[#This Row],[id_emploi]],Emplois[#All],3,0) -> Maïeutique | P8: =IF(AND(Contrats[[#This Row],[debut]]<=Résultats!D$11,Contrats[[#This Row],[fin_imputee]]>=Résultats!D$11),1,0) -> 0
A9: 7 | B9: 36593 | D9: =IF(Contrats[[#This Row],[fin]]="",D$1, Contrats[[#This Row],[fin]]) -> 45900 | E9: cdi | F9: 6 | G9: 286 | H9: 1.0 | I9: 402 | J9: jour | K9: heures | L9: 0 | M9: 1 | N9: 0 | O9: =VLOOKUP(Contrats[[#This Row],[id_emploi]],Emplois[#All],3,0) -> Administratif/médical | P9: =IF(AND(Contrats[[#This Row],[debut]]<=Résultats!D$11,Contrats[[#This Row],[fin_imputee]]>=Résultats!D$11),1,0) -> 1
A10: 8 | B10: 36686 | C10: 37204 | D10: =IF(Contrats[[#This Row],[fin]]="",D$1, Contrats[[#This Row],[fin]]) -> 37204 | E10: cdd | F10: 7 | G10: 221 | H10: 0.8 | I10: 318 | J10: nuit | K10: heures | L10: 0 | M10: 1 | N10: 0 | O10: =VLOOKUP(Contrats[[#This Row],[id_emploi]],Emplois[#All],3,0) -> Soins infirmiers | P10: =IF(AND(Contrats[[#This Row],[debut]]<=Résultats!D$11,Contrats[[#This Row],[fin_imputee]]>=Résultats!D$11),1,0) -> 0
A11: 9 | B11: 37317 | C11: 37927 | D11: =IF(Contrats[[#This Row],[fin]]="",D$1, Contrats[[#This Row],[fin]]) -> 37927 | E11: cdi | F11: 8 | G11: 216 | H11: 0.8 | I11: 309 | J11: forfait | K11: jours | L11: 0 | M11: 1 | N11: 1 | O11: =VLOOKUP(Contrats[[#This Row],[id_emploi]],Emplois[#All],3,0) -> Administratif | P11: =IF(AND(Contrats[[#This Row],[debut]]<=Résultats!D$11,Contrats[[#This Row],[fin_imputee]]>=Résultats!D$11),1,0) -> 0
A12: 10 | B12: 38729 | D12: =IF(Contrats[[#This Row],[fin]]="",D$1, Contrats[[#This Row],[fin]]) -> 45900 | E12: cdi | F12: 9 | G12: 191 | H12: 1.0 | I12: 266 | J12: jour | K12: heures | L12: 1 | M12: 1 | N12: 1 | O12: =VLOOKUP(Contrats[[#This Row],[id_emploi]],Emplois[#All],3,0) -> Médical | P12: =IF(AND(Contrats[[#This Row],[debut]]<=Résultats!D$11,Contrats[[#This Row],[fin_imputee]]>=Résultats!D$11),1,0) -> 1
A13: 11 | B13: 37175 | D13: =IF(Contrats[[#This Row],[fin]]="",D$1, Contrats[[#This Row],[fin]]) -> 45900 | E13: cdi | F13: 10 | G13: 31 | H13: 1.0 | I13: 67 | J13: jour | K13: heures | L13: 1 | M13: 0 | N13: 1 | O13: =VLOOKUP(Contrats[[#This Row],[id_emploi]],Emplois[#All],3,0) -> Médical | P13: =IF(AND(Contrats[[#This Row],[debut]]<=Résultats!D$11,Contrats[[#This Row],[fin_imputee]]>=Résultats!D$11),1,0) -> 1
A14: 12 | B14: 37521 | C14: 38190 | D14: =IF(Contrats[[#This Row],[fin]]="",D$1, Contrats[[#This Row],[fin]]) -> 38190 | E14: cdi | F14: 11 | G14: 205 | H14: 0.5 | I14: 295 | J14: nuit | K14: heures | L14: 0 | M14: 0 | N14: 1 | O14: =VLOOKUP(Contrats[[#This Row],[id_emploi]],Emplois[#All],3,0) -> Soins infirmiers | P14: =IF(AND(Contrats[[#This Row],[debut]]<=Résultats!D$11,Contrats[[#This Row],[fin_imputee]]>=Résultats!D$11),1,0) -> 0
A15: 13 | B15: 38228 | C15: 38836 | D15: =IF(Contrats[[#This Row],[fin]]="",D$1, Contrats[[#This Row],[fin]]) -> 38836 | E15: cdi | F15: 11 | G15: 224 | H15: 1.0 | I15: 322 | J15: nuit | K15: heures | L15: 0 | M15: 0 | N15: 1 | O15: =VLOOKUP(Contrats[[#This Row],[id_emploi]],Emplois[#All],3,0) -> Soins infirmiers | P15: =IF(AND(Contrats[[#This Row],[debut]]<=Résultats!D$11,Contrats[[#This Row],[fin_imputee]]>=Résultats!D$11),1,0) -> 0
A16: 14 | B16: 36653 | C16: 37079 | D16: =IF(Contrats[[#This Row],[fin]]="",D$1, Contrats[[#This Row],[fin]]) -> 37079 | E16: cdi | F16: 12 | G16: 297 | H16: 1.0 | I16: 414 | J16: forfait | K16: jours | L16: 0 | M16: 1 | N16: 1 | O16: =VLOOKUP(Contrats[[#This Row],[id_emploi]],Emplois[#All],3,0) -> Médical | P16: =IF(AND(Contrats[[#This Row],[debut]]<=Résultats!D$11,Contrats[[#This Row],[fin_imputee]]>=Résultats!D$11),1,0) -> 0
A17: 15 | B17: 37137 | C17: 37471 | D17: =IF(Contrats[[#This Row],[fin]]="",D$1, Contrats[[#This Row],[fin]]) -> 37471 | E17: cdd | F17: 12 | G17: 297 | H17: 1.0 | I17: 414 | J17: forfait | K17: jours | L17: 1 | M17: 1 | N17: 1 | O17: =VLOOKUP(Contrats[[#This Row],[id_emploi]],Emplois[#All],3,0) -> Médical | P17: =IF(AND(Contrats[[#This Row],[debut]]<=Résultats!D$11,Contrats[[#This Row],[fin_imputee]]>=Résultats!D$11),1,0) -> 0
A18: 16 | B18: 37500 | C18: 37956 | D18: =IF(Contrats[[#This Row],[fin]]="",D$1, Contrats[[#This Row],[fin]]) -> 37956 | E18: cdd | F18: 12 | G18: 297 | H18: 1.0 | I18: 414 | J18: forfait | K18: jours | L18: 0 | M18: 1 | N18: 1 | O18: =VLOOKUP(Contrats[[#This Row],[id_emploi]],Emplois[#All],3,0) -> Médical | P18: =IF(AND(Contrats[[#This Row],[debut]]<=Résultats!D$11,Contrats[[#This Row],[fin_imputee]]>=Résultats!D$11),1,0) -> 0
A19: 17 | B19: 38000 | C19: 38486 | D19: =IF(Contrats[[#This Row],[fin]]="",D$1, Contrats[[#This Row],[fin]]) -> 38486 | E19: cdi | F19: 12 | G19: 297 | H19: 0.5 | I19: 414 | J19: forfait | K19: jours | L19: 0 | M19: 1 | N19: 1 | O19: =VLOOKUP(Contrats[[#This Row],[id_emploi]],Emplois[#All],3,0) -> Médical | P19: =IF(AND(Contrats[[#This Row],[debut]]<=Résultats!D$11,Contrats[[#This Row],[fin_imputee]]>=Résultats!D$11),1,0) -> 0
A20: 18 | B20: 38532 | D20: =IF(Contrats[[#This Row],[fin]]="",D$1, Contrats[[#This Row],[fin]]) -> 45900 | E20: cdi | F20: 12 | G20: 297 | H20: 1.0 | I20: 414 | J20: forfait | K20: jours | L20: 0 | M20: 0 | N20: 1 | O20: =VLOOKUP(Contrats[[#This Row],[id_emploi]],Emplois[#All],3,0) -> Médical | P20: =IF(AND(Contrats[[#This Row],[debut]]<=Résultats!D$11,Contrats[[#This Row],[fin_imputee]]>=Résultats!D$11),1,0) -> 1
A21: 19 | B21: 37117 | C21: 37301 | D21: =IF(Contrats[[#This Row],[fin]]="",D$1, Contrats[[#This Row],[fin]]) -> 37301 | E21: cdi | F21: 13 | G21: 254 | H21: 0.5 | I21: 357 | J21: forfait | K21: jours | L21: 0 | M21: 1 | N21: 1 | O21: =VLOOKUP(Contrats[[#This Row],[id_emploi]],Emplois[#All],3,0) -> Pharmacie | P21: =IF(AND(Contrats[[#This Row],[debut]]<=Résultats!D$11,Contrats[[#This Row],[fin_imputee]]>=Résultats!D$11),1,0) -> 0
A22: 20 | B22: 37317 | C22: 37531 | D22: =IF(Contrats[[#This Row],[fin]]="",D$1, Contrats[[#This Row],[fin]]) -> 37531 | E22: apprenti | F22: 13 | G22: 254 | H22: 1.0 | I22: 357 | J22: forfait | K22: jours | L22: 0 | M22: 1 | N22: 1 | O22: =VLOOKUP(Contrats[[#This Row],[id_emploi]],Emplois[#All],3,0) -> Pharmacie | P22: =IF(AND(Contrats[[#This Row],[debut]]<=Résultats!D$11,Contrats[[#This Row],[fin_imputee]]>=Résultats!D$11),1,0) -> 0
A23: 21 | B23: 37564 | C23: 37929 | D23: =IF(Contrats[[#This Row],[fin]]="",D$1, Contrats[[#This Row],[fin]]) -> 37929 | E23: cdi | F23: 13 | G23: 254 | H23: 1.0 | I23: 357 | J23: forfait | K23: jours | L23: 0 | M23: 0 | N23: 1 | O23: =VLOOKUP(Contrats[[#This Row],[id_emploi]],Emplois[#All],3,0) -> Pharmacie | P23: =IF(AND(Contrats[[#This Row],[debut]]<=Résultats!D$11,Contrats[[#This Row],[fin_imputee]]>=Résultats!D$11),1,0) -> 0
A24: 22 | B24: 36664 | C24: 37274 | D24: =IF(Contrats[[#This Row],[fin]]="",D$1, Contrats[[#This Row],[fin]]) -> 37274 | E24: cdi | F24: 14 | G24: 196 | H24: 1.0 | I24: 277 | J24: jour | K24: heures | L24: 1 | M24: 0 | N24: 1 | O24: =VLOOKUP(Contrats[[#This Row],[id_emploi]],Emplois[#All],3,0) -> Médical | P24: =IF(AND(Contrats[[#This Row],[debut]]<=Résultats!D$11,Contrats[[#This Row],[fin_imputee]]>=Résultats!D$11),1,0) -> 0
A25: 23 | B25: 37296 | C25: 37689 | D25: =IF(Contrats[[#This Row],[fin]]="",D$1, Contrats[[#This Row],[fin]]) -> 37689 | E25: cdi | F25: 14 | G25: 196 | H25: 0.5 | I25: 277 | J25: jour | K25: heures | L25: 0 | M25: 1 | N25: 1 | O25: =VLOOKUP(Contrats[[#This Row],[id_emploi]],Emplois[#All],3,0) -> Médical | P25: =IF(AND(Contrats[[#This Row],[debut]]<=Résultats!D$11,Contrats[[#This Row],[fin_imputee]]>=Résultats!D$11),1,0) -> 0
A26: 24 | B26: 37030 | C26: 37609 | D26: =IF(Contrats[[#This Row],[fin]]="",D$1, Contrats[[#This Row],[fin]]) -> 37609 | E26: cdi | F26: 15 | G26: 16 | H26: 0.8 | I26: 40 | J26: jour | K26: heures | L26: 0 | M26: 0 | N26: 1 | O26: =VLOOKUP(Contrats[[#This Row],[id_emploi]],Emplois[#All],3,0) -> Médical | P26: =IF(AND(Contrats[[#This Row],[debut]]<=Résultats!D$11,Contrats[[#This Row],[fin_imputee]]>=Résultats!D$11),1,0) -> 0
A27: 25 | B27: 37416 | D27: =IF(Contrats[[#This Row],[fin]]="",D$1, Contrats[[#This Row],[fin]]) -> 45900 | E27: cdi | F27: 16 | G27: 49 | H27: 1.0 | I27: 99 | J27: nuit | K27: heures | L27: 0 | M27: 1 | N27: 1 | O27: =VLOOKUP(Contrats[[#This Row],[id_emploi]],Emplois[#All],3,0) -> Soins infirmiers | P27: =IF(AND(Contrats[[#This Row],[debut]]<=Résultats!D$11,Contrats[[#This Row],[fin_imputee]]>=Résultats!D$11),1,0) -> 1
A28: 26 | B28: 36561 | C28: 37077 | D28: =IF(Contrats[[#This Row],[fin]]="",D$1, Contrats[[#This Row],[fin]]) -> 37077 | E28: cdi | F28: 17 | G28: 263 | H28: 1.0 | I28: 371 | J28: astreinte | K28: astreinte | L28: 0 | M28: 0 | N28: 0 | O28: =VLOOKUP(Contrats[[#This Row],[id_emploi]],Emplois[#All],3,0) -> Bloc opératoire | P28: =IF(AND(Contrats[[#This Row],[debut]]<=Résultats!D$11,Contrats[[#This Row],[fin_imputee]]>=Résultats!D$11),1,0) -> 0
A29: 27 | B29: 36947 | C29: 37097 | D29: =IF(Contrats[[#This Row],[fin]]="",D$1, Contrats[[#This Row],[fin]]) -> 37097 | E29: cdd | F29: 18 | G29: 256 | H29: 1.0 | I29: 359 | J29: jour | K29: heures | L29: 0 | M29: 1 | N29: 1 | O29: =VLOOKUP(Contrats[[#This Row],[id_emploi]],Emplois[#All],3,0) -> Soins infirmiers | P29: =IF(AND(Contrats[[#This Row],[debut]]<=Résultats!D$11,Contrats[[#This Row],[fin_imputee]]>=Résultats!D$11),1,0) -> 0
A30: 28 | B30: 37147 | C30: 37754 | D30: =IF(Contrats[[#This Row],[fin]]="",D$1, Contrats[[#This Row],[fin]]) -> 37754 | E30: cdi | F30: 18 | G30: 256 | H30: 1.0 | I30: 359 | J30: jour | K30: heures | L30: 0 | M30: 1 | N30: 1 | O30: =VLOOKUP(Contrats[[#This Row],[id_emploi]],Emplois[#All],3,0) -> Soins infirmiers | P30: =IF(AND(Contrats[[#This Row],[debut]]<=Résultats!D$11,Contrats[[#This Row],[fin_imputee]]>=Résultats!D$11),1,0) -> 0
A31: 29 | B31: 36948 | D31: =IF(Contrats[[#This Row],[fin]]="",D$1, Contrats[[#This Row],[fin]]) -> 45900 | E31: cdi | F31: 19 | G31: 260 | H31: 1.0 | I31: 364 | J31: nuit | K31: heures | L31: 1 | M31: 0 | N31: 1 | O31: =VLOOKUP(Contrats[[#This Row],[id_emploi]],Emplois[#All],3,0) -> Soins infirmiers | P31: =IF(AND(Contrats[[#This Row],[debut]]<=Résultats!D$11,Contrats[[#This Row],[fin_imputee]]>=Résultats!D$11),1,0) -> 1
A32: 30 | B32: 36751 | D32: =IF(Contrats[[#This Row],[fin]]="",D$1, Contrats[[#This Row],[fin]]) -> 45900 | E32: cdi | F32: 20 | G32: 201 | H32: 1.0 | I32: 286 | J32: forfait | K32: jours | L32: 0 | M32: 0 | N32: 0 | O32: =VLOOKUP(Contrats[[#This Row],[id_emploi]],Emplois[#All],3,0) -> Bloc opératoire | P32: =IF(AND(Contrats[[#This Row],[debut]]<=Résultats!D$11,Contrats[[#This Row],[fin_imputee]]>=Résultats!D$11),1,0) -> 1
A33: 31 | B33: 37279 | D33: =IF(Contrats[[#This Row],[fin]]="",D$1, Contrats[[#This Row],[fin]]) -> 45900 | E33: cdi | F33: 21 | G33: 299 | H33: 1.0 | I33: 416 | J33: nuit | K33: heures | L33: 0 | M33: 1 | N33: 1 | O33: =VLOOKUP(Contrats[[#This Row],[id_emploi]],Emplois[#All],3,0) -> Soins infirmiers | P33: =IF(AND(Contrats[[#This Row],[debut]]<=Résultats!D$11,Contrats[[#This Row],[fin_imputee]]>=Résultats!D$11),1,0) -> 1
A34: 32 | B34: 40884 | C34: 41159 | D34: =IF(Contrats[[#This Row],[fin]]="",D$1, Contrats[[#This Row],[fin]]) -> 41159 | E34: cdi | F34: 22 | G34: 29 | H34: 1.0 | I34: 63 | J34: jour | K34: heures | L34: 0 | M34: 0 | N34: 1 | O34: =VLOOKUP(Contrats[[#This Row],[id_emploi]],Emplois[#All],3,0) -> Médical | P34: =IF(AND(Contrats[[#This Row],[debut]]<=Résultats!D$11,Contrats[[#This Row],[fin_imputee]]>=Résultats!D$11),1,0) -> 0
A35: 33 | B35: 37315 | C35: 37496 | D35: =IF(Contrats[[#This Row],[fin]]="",D$1, Contrats[[#This Row],[fin]]) -> 37496 | E35: cdi | F35: 23 | G35: 70 | H35: 1.0 | I35: 124 | J35: nuit | K35: heures | L35: 0 | M35: 0 | N35: 1 | O35: =VLOOKUP(Contrats[[#This Row],[id_emploi]],Emplois[#All],3,0) -> Laboratoire | P35: =IF(AND(Contrats[[#This Row],[debut]]<=Résultats!D$11,Contrats[[#This Row],[fin_imputee]]>=Résultats!D$11),1,0) -> 0
A36: 34 | B36: 37519 | D36: =IF(Contrats[[#This Row],[fin]]="",D$1, Contrats[[#This Row],[fin]]) -> 45900 | E36: cdi | F36: 23 | G36: 70 | H36: 0.8 | I36: 123 | J36: jour | K36: heures | L36: 0 | M36: 1 | N36: 1 | O36: =VLOOKUP(Contrats[[#This Row],[id_emploi]],Emplois[#All],3,0) -> Laboratoire | P36: =IF(AND(Contrats[[#This Row],[debut]]<=Résultats!D$11,Contrats[[#This Row],[fin_imputee]]>=Résultats!D$11),1,0) -> 1
A37: 35 | B37: 42401 | C37: 45992 | D37: =IF(Contrats[[#This Row],[fin]]="",D$1, Contrats[[#This Row],[fin]]) -> 45992 | E37: cdd | F37: 24 | G37: 256 | H37: 1.0 | I37: 360 | J37: nuit | K37: heures | L37: 0 | M37: 0 | N37: 1 | O37: =VLOOKUP(Contrats[[#This Row],[id_emploi]],Emplois[#All],3,0) -> Soins infirmiers | P37: =IF(AND(Contrats[[#This Row],[debut]]<=Résultats!D$11,Contrats[[#This Row],[fin_imputee]]>=Résultats!D$11),1,0) -> 1
A38: 36 | B38: 37260 | C38: 37411 | D38: =IF(Contrats[[#This Row],[fin]]="",D$1, Contrats[[#This Row],[fin]]) -> 37411 | E38: cdd | F38: 25 | G38: 106 | H38: 1.0 | I38: 166 | J38: forfait | K38: jours | L38: 0 | M38: 1 | N38: 1 | O38: =VLOOKUP(Contrats[[#This Row],[id_emploi]],Emplois[#All],3,0) -> Information médicale | P38: =IF(AND(Contrats[[#This Row],[debut]]<=Résultats!D$11,Contrats[[#This Row],[fin_imputee]]>=Résultats!D$11),1,0) -> 0
A39: 37 | B39: 36870 | C39: 37174 | D39: =IF(Contrats[[#This Row],[fin]]="",D$1, Contrats[[#This Row],[fin]]) -> 37174 | E39: cdd | F39: 26 | G39: 61 | H39: 1.0 | I39: 111 | J39: jour | K39: heures | L39: 1 | M39: 1 | N39: 1 | O39: =VLOOKUP(Contrats[[#This Row],[id_emploi]],Emplois[#All],3,0) -> Rééducation | P39: =IF(AND(Contrats[[#This Row],[debut]]<=Résultats!D$11,Contrats[[#This Row],[fin_imputee]]>=Résultats!D$11),1,0) -> 0
A40: 38 | B40: 37218 | C40: 37583 | D40: =IF(Contrats[[#This Row],[fin]]="",D$1, Contrats[[#This Row],[fin]]) -> 37583 | E40: cdi | F40: 27 | G40: 75 | H40: 1.0 | I40: 132 | J40: jour | K40: heures | L40: 0 | M40: 1 | N40: 1 | O40: =VLOOKUP(Contrats[[#This Row],[id_emploi]],Emplois[#All],3,0) -> Pharmacie | P40: =IF(AND(Contrats[[#This Row],[debut]]<=Résultats!D$11,Contrats[[#This Row],[fin_imputee]]>=Résultats!D$11),1,0) -> 0
...

Sheet personnes
A1: id | B1: nom | C1: prénom | D1: date de naissance | E1: adresse rue | F1: adresse code postal | G1: adresse localité | H1: genre
A2: 1 | B2: Alvarez | C2: Maria | D2: 30381 | E2: 12 Impasse de l'Adré | F2: 13800.0 | G2: Istres | H2: F
A3: 2 | B3: Belkacem | C3: Ibrahima | D3: 30546 | E3: 5 Impasse de l'Adré | F3: 13800.0 | G3: Istres | H3: M
A4: 3 | B4: Nikolić | C4: Hugo | D4: 33903 | E4: 62 Rue d'Endoume | F4: 13007.0 | G4: Marseille | H4: M
A5: 4 | B5: Youssouf | C5: Miguel | D5: 28028 | E5: 12 Place du Marché des Capucins | F5: 13001.0 | G5: Marseille | H5: M
A6: 5 | B6: Alvarez | C6: Noah | D6: 16560 | E6: 1b Chemin des Aubépines | F6: 13700.0 | G6: Marignane | H6: M
A7: 6 | B7: Elbaz | C7: Mehdi | D7: 27540 | E7: 127 Rue d'Aubagne | F7: 13006.0 | G7: Marseille | H7: M
A8: 7 | B8: Traoré | C8: Soumaya | D8: 21797 | E8: 19 Rue Savorgnan de Brazza | F8: 13700.0 | G8: Marignane | H8: F
A9: 8 | B9: Casabianca | C9: Salma | D9: 18252 | E9: 2 Place Sadi-Carnot | F9: 13001.0 | G9: Marseille | H9: F
A10: 9 | B10: Bernard | C10: Rania | D10: 31738 | E10: 3 Quai Marceau | F10: 13500.0 | G10: Martigues | H10: F
A11: 10 | B11: Benkhelifa | C11: Beatriz | D11: 22922 | E11: 75 Cours Gambetta | F11: 13001.0 | G11: Marseille | H11: F
A12: 11 | B12: Perrot | C12: Javier | D12: 22010 | E12: 20 Traverse Montcault | F12: 13013.0 | G12: Marseille | H12: M
A13: 12 | B13: Diallo | C13: Noa | D13: 26932 | E13: 9 Parc Beaulieu | F13: 13700.0 | G13: Marignane | H13: F
... A1816: 1815 | B1816: Ricci | C1816: Armen | D1816: 18670 | E1816: 57 Cours Gambetta | F1816: 13001.0 | G1816: Marseille | H1816: M
A1817: 1816 | B1817: Papadopoulos | C1817: Hugo | D1817: 24123 | E1817: 2449 avenue du Capitaine Corvette Paul Brutus | G1817: Les Pennes-Mirabeau | H1817: M
A1818: 1817 | B1818: Garcia | C1818: Ahmed | D1818: 25613 | E1818: 9 Quai Poterne | F1818: 13500.0 | G1818: Martigues | H1818: M
A1819: 1818 | B1819: Bernard | C1819: Naïma | D1819: 17241 | E1819: 5 Place Sadi-Carnot | F1819: 13002.0 | G1819: Marseille | H1819: F
A1820: 1819 | B1820: Colonna | C1820: Beatriz | D1820: 33447 | E1820: 2 Impasse Olivier Messiaen | F1820: 13170.0 | G1820: Les Pennes-Mirabeau | H1820: F
A1821: 1820 | B1821: Silva | C1821: João | D1821: 34544 | E1821: 9B Rue Marius Reynaud | F1821: 13090.0 | G1821: Aix-en-Provence | H1821: M
A1822: 1821 | B1822: Martin | C1822: Raphaël | D1822: 20982 | E1822: 3 Boulevard Élysée Reclus | F1822: 13004.0 | G1822: Marseille | H1822: M
A1823: 1822 | B1823: Rossi | C1823: Rui | D1823: 34675 | E1823: 1 Plage de l'Estaque | F1823: 13016.0 | G1823: Marseille | H1823: M
A1824: 1823 | B1824: Saïdi | C1824: Manon | D1824: 29151 | E1824: 2 Rue Gabriel Sénac de Meilhan | F1824: 13001.0 | G1824: Marseille | H1824: F
A1825: 1824 | B1825: Fernandez | C1825: Fatima | D1825: 35203 | E1825: 11 Cours Voltaire | F1825: 13400.0 | G1825: Aubagne | H1825: F
A1826: 1825 | B1826: Ndiaye | C1826: Mathis | D1826: 32229 | E1826: 17 Rue Pastoret | F1826: 13006.0 | G1826: Marseille | H1826: M
A1827: 1826 | B1827: Colonna | C1827: Élise | D1827: 32288 | E1827: 76 Boulevard Frédéric Mistral | F1827: 13800.0 | G1827: Istres | H1827: F
A1828: 1827 | B1828: Ricci | C1828: Élise | D1828: 26904 | E1828: 11 Cours Gambetta | F1828: 13001.0 | G1828: Marseille | H1828: F
A1829: 1828 | B1829: Dubois | C1829: Antoine | D1829: 21935 | E1829: 818 L Audience Zi Secteur 81 | F1829: 13270.0 | G1829: Fos-sur-Mer | H1829: M
... A3001: 3000 | B3001: Traoré | C3001: Ibrahima | D3001: 23521 | E3001: 190 Avenue des Vallins | F3001: 13895.0 | G3001: Fos-sur-Mer | H3001: M

Sheet emplois
A1: id | B1: libellé | C1: catégorie | D1: rythme
A2: 1 | B2: Médecin généraliste hospitalier | C2: Médical | D2: jour; astreintes
A3: 2 | B3: Médecin anesthésiste-réanimateur | C3: Médical | D3: jour/nuit; astreintes
A4: 3 | B4: Médecin réanimateur médical | C4: Médical | D4: jour/nuit; astreintes
A5: 4 | B5: Chirurgien digestif | C5: Médical | D5: jour; astreintes; bloc
A6: 5 | B6: Chirurgien orthopédiste | C6: Médical | D6: jour; astreintes; bloc
A7: 6 | B7: Chirurgien viscéral | C7: Médical | D7: jour; astreintes; bloc
A8: 7 | B8: Chirurgien vasculaire | C8: Médical | D8: jour; astreintes; bloc
A9: 8 | B9: Neurochirurgien | C9: Médical | D9: jour; astreintes; bloc
A10: 9 | B10: Chirurgien cardiaque | C10: Médical | D10: jour; astreintes; bloc
A11: 10 | B11: Chirurgien ORL | C11: Médical | D11: jour; astreintes; bloc
A12: 11 | B12: Chirurgien maxillo-facial | C12: Médical | D12: jour; astreintes; bloc
A13: 12 | B13: Gynécologue-obstétricien | C13: Médical | D13: jour/nuit; astreintes; bloc
... A300: 299 | B300: Aide-soignant EHPAD | C300: Soins infirmiers | D300: jour/nuit

Sheet temps_du_2024_09
A1: mois | B1: id_pers | C1: id_contrat | D1: id_emploi | E1: id_temps | F1: plage_type | G1: start | H1: end | I1: duree_heures | J1: unite | K1: quota_source
A2: 45536 | B2: 4 | C2: 5 | D2: 216 | E2: 309 | F2: forfait | G2: 45537.375 | H2: 45537.708 | I2: 8.0 | J2: jours | K2: 10.53
A3: 45536 | B3: 4 | C3: 5 | D3: 216 | E3: 309 | F3: forfait | G3: 45538.375 | H3: 45538.708 | I3: 8.0 | J3: jours | K3: 10.53
A4: 45536 | B4: 4 | C4: 5 | D4: 216 | E4: 309 | F4: forfait | G4: 45539.375 | H4: 45539.708 | I4: 8.0 | J4: jours | K4: 10.53
A5: 45536 | B5: 4 | C5: 5 | D5: 216 | E5: 309 | F5: forfait | G5: 45540.375 | H5: 45540.708 | I5: 8.0 | J5: jours | K5: 10.53
A6: 45536 | B6: 4 | C6: 5 | D6: 216 | E6: 309 | F6: forfait | G6: 45541.375 | H6: 45541.708 | I6: 8.0 | J6: jours | K6: 10.53
A7: 45536 | B7: 4 | C7: 5 | D7: 216 | E7: 309 | F7: forfait | G7: 45544.375 | H7: 45544.708 | I7: 8.0 | J7: jours | K7: 10.53
A8: 45536 | B8: 4 | C8: 5 | D8: 216 | E8: 309 | F8: forfait | G8: 45545.375 | H8: 45545.708 | I8: 8.0 | J8: jours | K8: 10.53
A9: 45536 | B9: 4 | C9: 5 | D9: 216 | E9: 309 | F9: forfait | G9: 45546.375 | H9: 45546.708 | I9: 8.0 | J9: jours | K9: 10.53
A10: 45536 | B10: 4 | C10: 5 | D10: 216 | E10: 309 | F10: forfait | G10: 45547.375 | H10: 45547.708 | I10: 8.0 | J10: jours | K10: 10.53
A11: 45536 | B11: 4 | C11: 5 | D11: 216 | E11: 309 | F11: forfait | G11: 45548.375 | H11: 45548.708 | I11: 8.0 | J11: jours | K11: 10.53
A12: 45536 | B12: 4 | C12: 5 | D12: 216 | E12: 309 | F12: forfait | G12: 45565.375 | H12: 45565.55 | I12: 4.2 | J12: jours | K12: 10.53
A13: 45536 | B13: 6 | C13: 7 | D13: 286 | E13: 402 | F13: jour | G13: 45537.333 | H13: 45537.646 | I13: 7.5 | J13: heures | K13: 132.08
... A13912: 45536 | B13912: 3000 | C13912: 4450 | D13912: 43 | E13912: 87 | F13912: nuit | G13912: 45561.812 | H13912: 45563.316 | I13912: 36.08 | J13912: heures | K13912: 132.08

Sheet absences
A1: id | B1: id_contrat | C1: code | D1: debut | E1: fin | F1: jours_ouvres
A2: 1 | B2: 5 | C2: MAL | D2: 45572 | E2: 45578 | F2: 5
A3: 2 | B3: 5 | C3: MAL | D3: 45591 | E3: 45598 | F3: 4
A4: 3 | B4: 5 | C4: MAL | D4: 45756 | E4: 45762 | F4: 5
A5: 4 | B5: 5 | C5: MAL | D5: 45807 | E5: 45810 | F5: 2
A6: 5 | B6: 5 | C6: MAL | D6: 45816 | E6: 45819 | F6: 2
A7: 6 | B7: 7 | C7: MAL | D7: 45541 | E7: 45545 | F7: 3
A8: 7 | B8: 7 | C8: MAL | D8: 45603 | E8: 45606 | F8: 2
A9: 8 | B9: 7 | C9: MAL | D9: 45612 | E9: 45615 | F9: 2
A10: 9 | B10: 7 | C10: DECE | D10: 45697 | E10: 45700 | F10: 3
A11: 10 | B11: 7 | C11: DECE | D11: 45701 | E11: 45704 | F11: 2
A12: 11 | B12: 7 | C12: DEME | D12: 45725 | E12: 45726 | F12: 1
A13: 12 | B13: 7 | C13: DEME | D13: 45726 | E13: 45727 | F13: 2
... A2587: 2586 | B2587: 4450 | C2587: MAL | D2587: 45847 | E2587: 45852 | F2587: 3

Sheet absences_types
A1: id | B1: code | C1: libellé | D1: famille | E1: type | F1: autorisation préalable | G1: assurance
A2: 1 | B2: MAL | C2: Maladie | D2: Maladie | E2: Maladie | F2: non | G2: CPAM
A3: 2 | B3: LMAL | C3: Longue maladie | D3: Maladie | E3: Longue maladie | F3: non | G3: CPAM
A4: 3 | B4: AT | C4: Accident de travail | D4: Accidentologie | E4: Accident de travail | F4: non | G4: CPAM
A5: 4 | B5: ATR | C5: Accident de trajet | D5: Accidentologie | E5: Accident de trajet | F5: non | G5: CPAM
A6: 5 | B6: MPRO | C6: Maladie professionnelle | D6: Accidentologie | E6: Maladie professionnelle | F6: non | G6: CPAM
A7: 6 | B7: CEDU | C7: Congé parental d'éducation | D7: Parentalité | E7: Congés d'éducation | F7: oui | G7: CAF
A8: 7 | B8: CPAT | C8: Congé de paternité | D8: Parentalité | E8: Congés de paternité | F8: oui | G8: CPAM
A9: 8 | B9: HFEM | C9: Heure femme enceinte | D9: Parentalité | E9: Heure femme enceinte | F9: oui | G9: Aucune
A10: 9 | B10: MAT | C10: Congé maternité | D10: Parentalité | E10: Maternité | F10: oui | G10: CPAM
A11: 10 | B11: CPTH | C11: Congé pathologique maternité | D11: Parentalité | E11: Congés pathologiques | F11: oui | G11: CPAM
A12: 11 | B12: DECE | C12: Décès d'un proche | D12: Événements familiaux | E12: Décès | F12: oui | G12: Aucune
A13: 12 | B13: DEME | C13: Déménagement | D13: Événements familiaux | E13: Déménagement | F13: oui | G13: Aucune
... A24: 23 | B24: SERV | C24: Service national ou militaire | D24: Absences non payées | E24: État | F24: non | G24: État

Sheet Sheet3

Sheet Sheet2

Sheet Sheet1
